[2024-01-19T14:48:29.736+0100] {taskinstance.py:1957} INFO - Dependencies all met for dep_context=non-requeueable deps ti=<TaskInstance: mobula_injest_data_dag.store_on_hdfs manual__2024-01-19T13:47:01.569827+00:00 [queued]>
[2024-01-19T14:48:29.747+0100] {taskinstance.py:1957} INFO - Dependencies all met for dep_context=requeueable deps ti=<TaskInstance: mobula_injest_data_dag.store_on_hdfs manual__2024-01-19T13:47:01.569827+00:00 [queued]>
[2024-01-19T14:48:29.750+0100] {taskinstance.py:2171} INFO - Starting attempt 1 of 2
[2024-01-19T14:48:29.964+0100] {taskinstance.py:2192} INFO - Executing <Task(PythonOperator): store_on_hdfs> on 2024-01-19 13:47:01.569827+00:00
[2024-01-19T14:48:30.070+0100] {standard_task_runner.py:60} INFO - Started process 5187 to run task
[2024-01-19T14:48:30.114+0100] {standard_task_runner.py:87} INFO - Running: ['airflow', 'tasks', 'run', 'mobula_injest_data_dag', 'store_on_hdfs', 'manual__2024-01-19T13:47:01.569827+00:00', '--job-id', '105', '--raw', '--subdir', 'DAGS_FOLDER/MobulaData.py', '--cfg-path', '/tmp/tmpbb33a7rb']
[2024-01-19T14:48:30.125+0100] {standard_task_runner.py:88} INFO - Job 105: Subtask store_on_hdfs
[2024-01-19T14:48:30.493+0100] {task_command.py:423} INFO - Running <TaskInstance: mobula_injest_data_dag.store_on_hdfs manual__2024-01-19T13:47:01.569827+00:00 [running]> on host ubuntu.ubuntu.virtualbox.org
[2024-01-19T14:48:31.062+0100] {taskinstance.py:2481} INFO - Exporting env vars: AIRFLOW_CTX_DAG_OWNER='jules' AIRFLOW_CTX_DAG_ID='mobula_injest_data_dag' AIRFLOW_CTX_TASK_ID='store_on_hdfs' AIRFLOW_CTX_EXECUTION_DATE='2024-01-19T13:47:01.569827+00:00' AIRFLOW_CTX_TRY_NUMBER='1' AIRFLOW_CTX_DAG_RUN_ID='manual__2024-01-19T13:47:01.569827+00:00'
[2024-01-19T14:48:31.729+0100] {client.py:192} INFO - Instantiated <InsecureClient(url='http://localhost:9870')>.
[2024-01-19T14:48:31.730+0100] {client.py:496} INFO - Writing to '/mobula/raw/CryptoList_14-48-31.json'.
[2024-01-19T14:48:31.734+0100] {taskinstance.py:2699} ERROR - Task failed with exception
Traceback (most recent call last):
  File "/home/ubuntu/.local/lib/python3.10/site-packages/urllib3/connection.py", line 174, in _new_conn
    conn = connection.create_connection(
  File "/home/ubuntu/.local/lib/python3.10/site-packages/urllib3/util/connection.py", line 95, in create_connection
    raise err
  File "/home/ubuntu/.local/lib/python3.10/site-packages/urllib3/util/connection.py", line 85, in create_connection
    sock.connect(sa)
ConnectionRefusedError: [Errno 111] Connection refused

During handling of the above exception, another exception occurred:

Traceback (most recent call last):
  File "/home/ubuntu/.local/lib/python3.10/site-packages/urllib3/connectionpool.py", line 715, in urlopen
    httplib_response = self._make_request(
  File "/home/ubuntu/.local/lib/python3.10/site-packages/urllib3/connectionpool.py", line 416, in _make_request
    conn.request(method, url, **httplib_request_kw)
  File "/home/ubuntu/.local/lib/python3.10/site-packages/urllib3/connection.py", line 244, in request
    super(HTTPConnection, self).request(method, url, body=body, headers=headers)
  File "/usr/lib/python3.10/http/client.py", line 1283, in request
    self._send_request(method, url, body, headers, encode_chunked)
  File "/usr/lib/python3.10/http/client.py", line 1329, in _send_request
    self.endheaders(body, encode_chunked=encode_chunked)
  File "/usr/lib/python3.10/http/client.py", line 1278, in endheaders
    self._send_output(message_body, encode_chunked=encode_chunked)
  File "/usr/lib/python3.10/http/client.py", line 1038, in _send_output
    self.send(msg)
  File "/usr/lib/python3.10/http/client.py", line 976, in send
    self.connect()
  File "/home/ubuntu/.local/lib/python3.10/site-packages/urllib3/connection.py", line 205, in connect
    conn = self._new_conn()
  File "/home/ubuntu/.local/lib/python3.10/site-packages/urllib3/connection.py", line 186, in _new_conn
    raise NewConnectionError(
urllib3.exceptions.NewConnectionError: <urllib3.connection.HTTPConnection object at 0x7fc895fbb040>: Failed to establish a new connection: [Errno 111] Connection refused

During handling of the above exception, another exception occurred:

Traceback (most recent call last):
  File "/home/ubuntu/.local/lib/python3.10/site-packages/requests/adapters.py", line 486, in send
    resp = conn.urlopen(
  File "/home/ubuntu/.local/lib/python3.10/site-packages/urllib3/connectionpool.py", line 799, in urlopen
    retries = retries.increment(
  File "/home/ubuntu/.local/lib/python3.10/site-packages/urllib3/util/retry.py", line 592, in increment
    raise MaxRetryError(_pool, url, error or ResponseError(cause))
urllib3.exceptions.MaxRetryError: HTTPConnectionPool(host='localhost', port=9870): Max retries exceeded with url: /webhdfs/v1/mobula/raw/CryptoList_14-48-31.json?user.name=hadoop&overwrite=True&op=CREATE (Caused by NewConnectionError('<urllib3.connection.HTTPConnection object at 0x7fc895fbb040>: Failed to establish a new connection: [Errno 111] Connection refused'))

During handling of the above exception, another exception occurred:

Traceback (most recent call last):
  File "/home/ubuntu/.local/lib/python3.10/site-packages/airflow/models/taskinstance.py", line 433, in _execute_task
    result = execute_callable(context=context, **execute_callable_kwargs)
  File "/home/ubuntu/.local/lib/python3.10/site-packages/airflow/operators/python.py", line 199, in execute
    return_value = self.execute_callable()
  File "/home/ubuntu/.local/lib/python3.10/site-packages/airflow/operators/python.py", line 216, in execute_callable
    return self.python_callable(*self.op_args, **self.op_kwargs)
  File "/home/ubuntu/airflow/dags/MobulaData.py", line 82, in store_on_hdfs
    with client.write(hdfs_path, overwrite=True) as writer:
  File "/usr/local/lib/python3.10/dist-packages/hdfs/client.py", line 497, in write
    res = self._create(
  File "/usr/local/lib/python3.10/dist-packages/hdfs/client.py", line 125, in api_handler
    raise err
  File "/usr/local/lib/python3.10/dist-packages/hdfs/client.py", line 102, in api_handler
    res = client._request(
  File "/usr/local/lib/python3.10/dist-packages/hdfs/client.py", line 209, in _request
    return self._session.request(
  File "/home/ubuntu/.local/lib/python3.10/site-packages/requests/sessions.py", line 589, in request
    resp = self.send(prep, **send_kwargs)
  File "/home/ubuntu/.local/lib/python3.10/site-packages/requests/sessions.py", line 703, in send
    r = adapter.send(request, **kwargs)
  File "/home/ubuntu/.local/lib/python3.10/site-packages/requests/adapters.py", line 519, in send
    raise ConnectionError(e, request=request)
requests.exceptions.ConnectionError: HTTPConnectionPool(host='localhost', port=9870): Max retries exceeded with url: /webhdfs/v1/mobula/raw/CryptoList_14-48-31.json?user.name=hadoop&overwrite=True&op=CREATE (Caused by NewConnectionError('<urllib3.connection.HTTPConnection object at 0x7fc895fbb040>: Failed to establish a new connection: [Errno 111] Connection refused'))
[2024-01-19T14:48:32.152+0100] {taskinstance.py:1138} INFO - Marking task as UP_FOR_RETRY. dag_id=mobula_injest_data_dag, task_id=store_on_hdfs, execution_date=20240119T134701, start_date=20240119T134829, end_date=20240119T134832
[2024-01-19T14:48:32.291+0100] {standard_task_runner.py:107} ERROR - Failed to execute job 105 for task store_on_hdfs (HTTPConnectionPool(host='localhost', port=9870): Max retries exceeded with url: /webhdfs/v1/mobula/raw/CryptoList_14-48-31.json?user.name=hadoop&overwrite=True&op=CREATE (Caused by NewConnectionError('<urllib3.connection.HTTPConnection object at 0x7fc895fbb040>: Failed to establish a new connection: [Errno 111] Connection refused')); 5187)
[2024-01-19T14:48:32.319+0100] {local_task_job_runner.py:234} INFO - Task exited with return code 1
[2024-01-19T14:48:32.356+0100] {taskinstance.py:3281} INFO - 0 downstream tasks scheduled from follow-on schedule check
